Workbook

Sheet 問題
A1: 班名 | B1: シーン | C1: No. | D1: 共通 | E1: 共／個 | F1: 問題 | G1: ｺﾐｭﾆｹｰｼｮﾝ | H1: 評価基準（ｺﾐｭﾆｹｰｼｮﾝ） | I1: 情報収集 | J1: 評価基準（情報収集） | K1: 情報分析 | L1: 評価基準（情報分析） | M1: 想像・先読み | N1: 評価基準（想像・先読み） | O1: 計画 | P1: 評価基準（計画）
A3: 00全班共通 | B3: シーン1 | C3: 1 | D3: 共通01 | E3: 共通 | F3: 発災当日18時すぎ 在宅勤務の残業中に激しい揺れに襲われましたが、ようやく揺れが収まりました。輻輳中でネットはつながりにくい状況です。 あなたならどのような行動をとりますか？ 何を使用し、何を行うか具体的に記述して下さい。 ※評価対象コンピテンシー：情報収集力、想像・先読み力、計画力 | I3: ● | J3: 1点：災害情報を自ら情報収集しようとしている 2点：災害情報に加えて、社内関係者の安否、被災状況、外にいる場合は家族の安否など、自ら情報収集しようとしている 3点：通信状況が悪いことを前提に、事前にチャットを送り送信されるのを待つなど、創意工夫をしながら情報収集をしようとしている | M3: ● | N3: 1点：余震や津波など、これから身の回りに起こることを想像できている 2点：自身に加えて、家族や、班員、サービスにどのような影響が出るのかを想像できている 3点：自身に加えて、家族や、班員、サービス影響について想像した内容を情報収集や計画に活用している | O3: ● | P3: 1点：自身の行動に対する計画を立てている 2点：自身に加えて、家族や、班員、サービスに対する計画を立てている 3点：想像力や収集情報をもとに、自身に加えて、家族や、班員、サービスに対する計画を立てている
A4: 00全班共通 | B4: シーン1 | C4: 2 | D4: 共通02 | E4: 共通 | F4: 発災当日18時すぎ Teamsチャットでの他班のやり取りを見ていると、首都圏内のドコモビジネスのオフィスや各社員の自宅もネットがつながりにくい状況のようです。小規模ながら余震も数回発生しています。 あなたならどのような行動をとりますか？ 何を使用し、何を行うか具体的に記述して下さい。 ※評価対象コンピテンシー：情報収集力 | I4: ● | J4: 1点：災害情報を自ら情報収集しようとしている 2点：広域での被害発生を想定し、社内関係者の安否やサービス影響に関する情報を自ら収集しようとしている 3点：広域での被害発生を想定し、今後の初動対応上重要となる情報を想定した上で、先手先手で社内関係者の安否やサービス影響に関する情報を自ら収集しようとしている
A5: 00全班共通 | B5: シーン1 | C5: 3 | D5: 共通03 | E5: 共通 | F5: 発災当日18時半 自身および家族の安全は確保されました。その中で以下の情報が同時に入ってきた場合に初動対応において、最優先で分析確認する情報はどれかを選択して下さい。また、その理由を「情報の確からしさ」と「リスクの大きさ（影響範囲×緊急性）」の観点で説明して下さい。 A：自治体公式SNS「○○市で震度6強を観測。被害状況を確認中」 B：SNS投稿「○○駅が全壊。多数のけが人がいる」 C：班員からのTeamsチャット「サービス班から●●サービスの通信断を検知の模様」 D：班員からのTeamsチャット「自宅周辺で停電している」 ※評価対象コンピテンシー：情報分析力 | K5: ● | L5: 1点：C以外を選択、もしくはCを選択し、信頼性、影響範囲、緊急性のうちの1つが説明されている 2点：Cを選択し、信頼性、影響範囲、緊急性のうちの2つが適切に説明されている 3点：Cを選択し、信頼性、影響範囲、緊急性の全てが適切に説明されている
A6: 00全班共通 | B6: シーン1 | C6: 4 | D6: 共通04 | E6: 共通 | I6: ● | J6: 1点：今後の対応に向けて、自ら情報収集しようとしている 2点：今後の対応に向け、班内や関連組織から情報収集している 3点：班の代表として、今後の対応に向け、班内や関連組織から情報収集している | O6: ● | P6: 1点：自身の行動に対する計画を立てている 2点：班活動に必要な計画を立てている 3点：班の代表として全社情報共有会議に参加することを想定して、班活動に必要な計画を立てている
A7: 00全班共通 | B7: シーン1 | C7: 5 | D7: 共通05 | E7: 共通 | F7: 発災当日19時 輻輳のため、携帯電話が繋がりにくい状態が継続しています。会社スマートフォンは通信ができる状況だが、自班の班長、班員は電話やチャットに応答せず、連絡がとれない状況です。 あなたならどのような行動をとりますか？ 何を使用し、何を行うか具体的に記述して下さい。 ※評価対象コンピテンシー：想像・先読み力、計画力 | M7: ● | N7: 1点：今後の流れを想像・先読みした上で行動している。 2点：連絡の取れない班長や班員の置かれている状況を想定しつつ、必要な行動を想定している。 3点：連絡の取れない班長や班員の置かれている状況を想定しつつ、当面は班の代表者としての対応が必要であることを想定している。 | O7: ● | P7: 1点：班長や班員と連絡を取るための計画を立てている 2点：班長や班員と連絡を取るための計画と、連絡が取れない場合の対応を計画している 3点：班の代表者目線で、情報統括班（危機管理室）との連携しながら、全社情報共有の輪への参加や危機管理DBの対応を計画している
A8: 00全班共通 | B8: シーン1 | C8: 6 | D8: 共通06 | E8: 共通 | F8: 発災当日19時 SNSで「某国から弾道ミサイルが発射された」との情報を見つけました。 あなたならどのような行動を行いますか？ 何を使用し、何を行うか具体的に記述して下さい。 ※評価対象コンピテンシー：情報収集力、情報分析力、想像・先読み力 | I8: ● | J8: 1点：弾道ミサイル情報に関して情報収集しようとしている 2点：国からの弾道ミサイル情報（Jアラート情報もしくはメールなど）に関して確認している 3点：国からの弾道ミサイル情報（Jアラート情報もしくはメールなど）を確認し、真である可能性が高い場合は、班の代表として今後の対応に向けた班内や関連組織から情報収集している | K8: ● | L8: 1点：情報の真偽を確かめている 2点：情報の真偽を確かめた上で、重大な影響を及ぼす可能性がある因子の特定している 3点：情報の真偽の確認と、重大な影響を及ぼす可能性がある因子を特定した上で、災対本部など、班間でのサポートを要請（注意喚起）する等の行動を起こしている | M8: ● | N8: ■情報分析の結果、偽と想定した場合 1点：フェイクニュースに惑わされている社員がいることを想定している 2点：類似のフェイクニュースが出ることを想定し、情報展開や注意喚起をしている 3点：情報展開や注意喚起に加えて、拡散しないように等、被害拡大抑止の行動をしている ■情報分析の結果、真と想定した場合 1点：本情報を把握していない社員がいることを想定している 2点：本情報を把握していない社員がいることを想定し、早急な注意喚起が必要であると想定している 3点：弾道ルートや落下予測地点に近い場所にいるメンバーには不要不急の外出を控え、原則自宅待機するよう指示が必要になることを想定している
A9: 00全班共通 | B9: シーン1 | C9: 7 | D9: 共通07 | E9: 共通 | F9: 発災当日19時半 全社情報共有の会議に参加したところ、自班で参加しているのはあなた一人でした。会議進行は西日本初動本部が行っています。 心の声（なんとか班員を招集しないといけないな・・・） あなたならどのような行動をとりますか？ 何を使用し、何を行うか具体的に記述して下さい。 ※評価対象コンピテンシー：情報収集力、計画力 | I9: ● | J9: 1点：班内の情報を収集しようとしている 2点：全社情報共有の会議に必要な情報に関して情報収集している 3点：情報収集の体制確立に向けて、班員の招集や他班との連携を検討している+L9 | O9: ● | P9: 1点：全社情報共有の会議での報告に向けた対応の計画をしている 2点：全社情報共有の会議で班の代表として、情報収集とそのまとめ、班行動の計画をしている 3点：全社情報共有の会議で班の代表として、情報収集とそのまとめ、班行動の計画と、他班への人的リソースの支援依頼など、実行に必要な調整まで計画している
A10: 00全班共通 | B10: シーン1 | C10: 8 | D10: 共通08 | E10: 共通 | F10: 発災当日19時半 NHKニュースの交通情報を会社スマートフォンで確認しました。 ・東京都、神奈川県、千葉県、埼玉県の鉄道は全線停止 ・道路は交通規制が発令され、各地で渋滞が発生中 （下図の高速道路、国道は一般車両通行止め、環状七号線内側方向の通行禁止） あなたならどのような行動をとりますか？ 何を使用し、何を行うか具体的に記述して下さい。 マップ引用（警視庁） https://www.keishicho.metro.tokyo.lg.jp/kurashi/saigai/shinsai_kisei/kisei/kisei_1.html ※評価対象コンピテンシー：情報収集力、情報分析力、想像・先読み力 | I10: ● | J10: 1点：必要な追加情報を収集している 2点：情報分析や今後の対応に必要な情報を収集している 3点：災害対応の全体像を見据えた上で、先手先手で指示をして、必要な情報を班内外から情報収集している | K10: ● | L10: 1点：自班やサービスへの影響がないかどうかを確かめている 2点：自班やサービスへの重大な影響を及ぼす可能性がある因子を特定している 3点：自班やサービスへの重大な影響を及ぼす可能性がある因子を特定した上で、災対本部など、班間でのサポートを要請（注意喚起）する等の行動を起こしている | M10: ● | N10: 1点：交通インフラ停止に伴う影響を想像している 2点：交通インフラ停止に伴う自班（帰宅困難者等）への影響を具体的に想像している 3点：交通インフラ停止に伴う自班（帰宅困難者等）やサービスへの影響を具体的に想像し、その対応や予防策を検討している
A11: 01本部長支援 | B11: シーン2 | C11: 1 | D11: 共通09 | E11: 共通 | F11: 発災当日20時 引き続き、ネットは繋がるが、携帯電話は輻輳中で繋がりにくい状況です。班員とは連絡がとれましたが、班長と連絡が取れません。 あなたならどのような行動をとりますか？ 何を使用し、何を行うか具体的に記述して下さい。 ※評価対象コンピテンシー：コミュニケーション力、情報収集力 | G11: ● | H11: 1点：班員への情報発信（一方向） 2点：自班内でコミュニケーションをとろうとしている（双方向） 3点：班長代理や副班長を中心とした体制を構築した上で、班間、班内でコミュニケーションをとろうとしている | I11: ● | J11: 1点：班長への連絡を試みている、班員から情報を収集している 2点：SNS等を含めて複数の手段を活用して班長への連絡を試みている 現時点での班内のとりまとめに必要な情報を特定した上で班員から情報収集している 3点：班長への連絡の試みや班員からの情報収集に加えて、情報統括班への支援依頼や体制構築などを行っている
A12: 01本部長支援 | B12: シーン2 | C12: 2 | D12: 共通10 | E12: 共通 | F12: 発災当日21時 西日本初動本部より、22時から全社情報共有の会議を実施する連絡が入りました。班長不在の中、会議開始までの1時間で班としてやるべきことを検討して下さい。 ※評価対象コンピテンシー：コミュニケーション力、計画力 | G12: ● | H12: 1点：班員への情報発信（一方向） 2点：班長と連絡をとり続けるとともに、全社情報共有の会議参加に向けて、自班内でコミュニケーションをとっている（双方向） 3点：班長と連絡をとり続けるとともに、班長代理や副班長を中心とした体制を構築した上で、班間、班内でコミュニケーションをとる準備をしている | O12: ● | P12: 1点：全社情報共有の会議への参加に向けた準備を計画している 2点：全社情報共有の会議へ班の代表として参加するための準備を計画をしている 3点：全社情報共有の会議で班の代表として参加するための準備を具体的に計画をしている ※班長代理の擁立、班の体制構築、収集情報のまとめ、班行動の計画、班間連携の計画
A13: 01本部長支援 | B13: シーン2 | C13: 3 | D13: 個別 | E13: 個別 | F13: 発災当日21時 会社スマートフォンを呼び出しているが応答はなく、Teamsチャットの既読もつかず、本部長（社長）の安否が不明です。 秘書室とは連絡が取れている状況です。 あなたならどのような行動をとりますか？ 何を使用し、何を行うか具体的に記述して下さい。 ※評価対象コンピテンシー：コミュニケーション力、情報収集力、計画力 | G13: ● | H13: ≪コミュニケーション≫班員と連絡が取れる状況になったので指示/展開が行えるか？ ・当事実を自身や周囲のメンバに展開 １点 ・当事実を踏まえ班内に展開し、情報収集を支持する ２点 ・当事象を班間に状況を共有、他班の協力を求める等アクションをおこしていれば ３点 | I13: ● | J13: ≪情報収集力≫班員と連絡が取れる状況になったので指示/展開が行えるか？ ・自ら情報収集しようとしている １点 ・指示をして、問題解決に必要な情報を収集している ２点 ⇒まずは誰が災害対応可能かを情報収集する ・先手先手で指示をして、問題解決に必要な情報を災対本部などで班内外から情報収集している ３点 | O13: ● | P13: ≪計画力≫本部長の代行対応について、そろそろ並行して計画する必要がある ・自身の周辺または自身の顧客に関わる影響と、その対応を検討できていれば １点 ・自身の周辺と自身の顧客に関わる影響と、その対応を検討できていれば ２点 ・今後の計画、中長期的な展望にかんする対策・計画を行う行動で ３点 （このまま社長との連絡が取れない場合は、副社長への代行が必要な点を考えられるか）
A14: 01本部長支援 | B14: シーン2 | C14: 4 | D14: 個別 | E14: 個別 | F14: 発災当日22時 本部長（社長）と連絡が取れましたが、身動きがとれない状況です。 本部長の代行を立てるためにあなたならどのような行動を行いますか？ 副社長A(代行順位1位) ：連絡は取れるが、動き出せるのは翌日18時以降の見通し。 副社長B(代行順位2位) ：連絡がとれない。 副社長C(代行順位3位) ：連絡が取れる。 ※評価対象コンピテンシー：情報分析力、想像・先読み力、計画力 | K14: ● | L14: ≪情報分析力≫ 時間シーンとしては、西初動本部長が代行しているため、発災直後としては、問題ない。（このまま） | M14: ● | N14: ≪想像・先読み≫ 24時間後を見据え、代取4役で行動可能な方を探す 社長の行動制限が発災24時間後に解除可能か？代行順位に従い、24時間後の状況を整理する | O14: ● | P14: ≪計画力≫ 万が一、社長代行で副社長を据える場合、代行解除の条件を整理し、当てはまる時間に代行解除を行う計画を立てる
A15: 01本部長支援 | B15: シーン2 | C15: 5 | D15: 個別 | E15: 個別 | F15: 発災翌日12時 西日本初動本部から、料金減免のHP掲載予定について問い合わせがありました。 あなたならどのような行動をとりますか？ 何を使用し、何を行うか具体的に記述して下さい。 ※評価対象コンピテンシー：コミュニケーション力、情報収集力 | G15: ● | H15: ≪コミュニケーション≫班員と連絡が取れる状況になったので指示/展開が行えるか？ ・当事実を自身や周囲のメンバに展開 １点 ・当事実を班内および本部長に展開 ２点 ・班間に状況を共有、さらにアクションをおこしていれば ３点 | I15: ● | J15: ≪情報収集力≫班員と連絡が取れる状況になったので指示/展開が行えるか？ ・適用条件等を自身で収集 1点 ・適用条件等を班員を巻き込んで収集、収集する体制を整える 2点 ・班間の情報を含め収集（ほかにあるのか等） 3点
A16: 01本部長支援 | B16: シーン2 | C16: 6 | D16: 個別 | E16: 個別 | F16: 発災翌日12時 西日本初動本部から、サービスごとの料金減免方針について問い合わせがありました。 あなたならどのような行動をとりますか？ 何を使用し、何を行うか具体的に記述して下さい。 ※評価対象コンピテンシー：コミュニケーション力 | G16: ● | H16: ≪コミュニケーション≫班員と連絡が取れる状況になったので指示/展開が行えるか？ ・自身や周囲のメンバに展開し、自己解決を図る １点 ・班内に展開し、班としての意思決定・回答をしている ２点 ・2点に加え、班間に状況を共有、さらにアクション（同類質問がないようにとか）をおこしていれば ３点
A17: 01本部長支援 | B17: シーン2 | C17: 7 | D17: 共通11 | E17: 共通 | F17: 発災翌日15時 班長と連絡が取れました。 あなたならどのような行動をとりますか？ 何を使用し、何を行うか具体的に記述して下さい。 ※評価対象コンピテンシー：コミュニケーション力 | G17: ● | H17: 1点：班長への情報提供（一方向） 2点：班長へのこれまでの対応事項や課題感に関するコミュニケーションをとっている（双方向） 3点：班長と双方向とのコミュニケーションに加えて、全社情報共有会議での報告や危機管理DBへの投入など、班外へも情報を共有し、コミュニケーションの活性化を行う
A18: 02広報 | B18: シーン2 | C18: 1 | D18: 共通09 | E18: 共通 | F18: 発災当日20時 引き続き、ネットは繋がるが、携帯電話は輻輳中で繋がりにくい状況です。班員とは連絡がとれましたが、班長と連絡が取れません。 あなたならどのような行動をとりますか？ 何を使用し、何を行うか具体的に記述して下さい。 ※評価対象コンピテンシー：コミュニケーション力、情報収集力 | G18: ● | H18: 1点：班員への情報発信（一方向） 2点：自班内でコミュニケーションをとろうとしている（双方向） 3点：班長代理や副班長を中心とした体制を構築した上で、班間、班内でコミュニケーションをとろうとしている | I18: ● | J18: 1点：班長への連絡を試みている、班員から情報を収集している 2点：SNS等を含めて複数の手段を活用して班長への連絡を試みている 現時点での班内のとりまとめに必要な情報を特定した上で班員から情報収集している 3点：班長への連絡の試みや班員からの情報収集に加えて、情報統括班への支援依頼や体制構築などを行っている
A19: 02広報 | B19: シーン2 | C19: 2 | D19: 共通10 | E19: 共通 | F19: 発災当日21時 西日本初動本部より、22時から全社情報共有の会議を実施する連絡が入りました。班長不在の中、会議開始までの1時間で班としてやるべきことを検討して下さい。 ※評価対象コンピテンシー：コミュニケーション力、計画力 | G19: ● | H19: 1点：班員への情報発信（一方向） 2点：班長と連絡をとり続けるとともに、全社情報共有の会議参加に向けて、自班内でコミュニケーションをとっている（双方向） 3点：班長と連絡をとり続けるとともに、班長代理や副班長を中心とした体制を構築した上で、班間、班内でコミュニケーションをとる準備をしている | O19: ● | P19: 1点：全社情報共有の会議への参加に向けた準備を計画している 2点：全社情報共有の会議へ班の代表として参加するための準備を計画をしている 3点：全社情報共有の会議で班の代表として参加するための準備を具体的に計画をしている ※班長代理の擁立、班の体制構築、収集情報のまとめ、班行動の計画、班間連携の計画
A20: 02広報 | B20: シーン2 | C20: 3 | D20: 個別 | E20: 個別 | F20: 発災当日21時 SNS上で、(実際には故障していない)「OCNがつながらない、NTTドコモビジネスの通信障害だ！」との投稿が200件/30分あったとSLCから電話がありました。 あなたならどのような行動をとりますか？ 何を使用し、何を行うか具体的に記述して下さい。 ※評価対象コンピテンシー：情報収集力、計画力 | I20: ● | J20: ≪情報収集力≫ ・自ら情報収集しようとしている １点 ・指示をして、問題解決に必要な情報を収集している ２点 ・先手先手で指示をして、問題解決に必要な情報を災対本部などで班内外から情報収集している ３点 | O20: ● | P20: ≪計画力≫ ・自分でできる対応を計画している １点 ・周囲の班員でできる対応を計画している ２点 ・災害対応の全体像を見据えたり、先読みした内容を踏まえた上で、既存ルールにこだわらず対応を計画している ３点
A21: 02広報 | B21: シーン2 | C21: 4 | D21: 個別 | E21: 個別 | F21: 発災当日22時 電話がつながりはじめました。NHKから電話で「NTTドコモビジネスのサービス故障の状況を30分以内に教えてほしい」と連絡がありました。その後、共同通信、読売新聞からも同様の電話が来ました。 あなたならどのような行動をとりますか？ 何を使用し、何を行うか具体的に記述して下さい。 ※評価対象コンピテンシー：コミュニケーション力、情報収集力 | G21: ● | H21: ≪コミュニケーション力≫ ・班内で指示/連絡をとろうとしている １点 ・班内、班間で具体的に意思疎通（傾聴＋伝達）している ２点 ・組織や立場を超えて、付加価値を付けた上で自身の考えを意思疎通（傾聴＋伝達）している ３点 | I21: ● | J21: ≪情報収集力≫ ・自ら情報収集しようとしている １点 ・指示をして、問題解決に必要な情報を収集している ２点 ⇒まずは誰が災害対応可能かを情報収集する ・先手先手で指示をして、問題解決に必要な情報を災対本部などで班内外から情報収集している ３点
A22: 02広報 | B22: シーン2 | C22: 5 | D22: 個別 | E22: 個別 | F22: 発災翌日12時 複数のサービスが故障しており、オフィシャルサイトのトップに故障情報が乱立しています。 あなたならどのような行動をとりますか？ 何を使用し、何を行うか具体的に記述して下さい。 ※評価対象コンピテンシー：計画力 | O22: ● | P22: ≪計画力≫ ・自分でできる対応を計画している １点 ・周囲の班員でできる対応を計画している ２点 ・災害対応の全体像を見据えたり、先読みした内容を踏まえた上で、既存ルールにこだわらず対応を計画している ３点
A23: 02広報 | B23: シーン2 | C23: 6 | D23: 個別 | E23: 個別 | F23: 発災翌日12時 ドコモ広報の担当者とのTeamsチャットのやり取りで、ドコモショップの店頭にて通信障害情報の掲示を1時間ごとに行うことが判明しました。 あなたならどのような行動を行いますか？ 何を使用し、何を行うか具体的に記述して下さい。 ※評価対象コンピテンシー：情報分析力、想像・先読み力 | K23: ● | L23: ≪情報分析力≫ ・情報分析（重大な影響を及ぼす可能性がある因子の特定）を試みている １点 ・情報分析を行い、重大な影響を及ぼす可能性がある因子の特定している ２点 ・情報分析を行い、重大な影響を及ぼす可能性がある因子の特定した上で、災対本部など、班間でのサポートを要請（注意喚起）する等の行動を起こしている ３点 | M23: ● | N23: ≪想像、先読み力≫ ・次に起こる事を想定しようとしている １点 ・次に起こる事を想定して、今できることを検討している ２点 ・災害対応の全体像を見据えた上で次に起こる事を想定して、具体的に対応や予防策を検討している ３点
A24: 02広報 | B24: シーン2 | C24: 7 | D24: 共通11 | E24: 共通 | F24: 発災翌日15時 班長と連絡が取れました。 あなたならどのような行動をとりますか？ 何を使用し、何を行うか具体的に記述して下さい。 ※評価対象コンピテンシー：コミュニケーション力 | G24: ● | H24: 1点：班長への情報提供（一方向） 2点：班長へのこれまでの対応事項や課題感に関するコミュニケーションをとっている（双方向） 3点：班長と双方向とのコミュニケーションに加えて、全社情報共有会議での報告や危機管理DBへの投入など、班外へも情報を共有し、コミュニケーションの活性化を行う
A25: 03総務 | B25: シーン2 | C25: 1 | D25: 共通09 | E25: 共通 | F25: 発災当日20時 引き続き、ネットは繋がるが、携帯電話は輻輳中で繋がりにくい状況です。班員とは連絡がとれましたが、班長と連絡が取れません。 あなたならどのような行動をとりますか？ 何を使用し、何を行うか具体的に記述して下さい。 ※評価対象コンピテンシー：コミュニケーション力、情報収集力 | G25: ● | H25: 1点：班員への情報発信（一方向） 2点：自班内でコミュニケーションをとろうとしている（双方向） 3点：班長代理や副班長を中心とした体制を構築した上で、班間、班内でコミュニケーションをとろうとしている | I25: ● | J25: 1点：班長への連絡を試みている、班員から情報を収集している 2点：SNS等を含めて複数の手段を活用して班長への連絡を試みている 現時点での班内のとりまとめに必要な情報を特定した上で班員から情報収集している 3点：班長への連絡の試みや班員からの情報収集に加えて、情報統括班への支援依頼や体制構築などを行っている
A26: 03総務 | B26: シーン2 | C26: 2 | D26: 共通10 | E26: 共通 | F26: 発災当日21時 西日本初動本部より、22時から全社情報共有の会議を実施する連絡が入りました。班長不在の中、会議開始までの1時間で班としてやるべきことを検討して下さい。 ※評価対象コンピテンシー：コミュニケーション力、計画力 | G26: ● | H26: 1点：班員への情報発信（一方向） 2点：班長と連絡をとり続けるとともに、全社情報共有の会議参加に向けて、自班内でコミュニケーションをとっている（双方向） 3点：班長と連絡をとり続けるとともに、班長代理や副班長を中心とした体制を構築した上で、班間、班内でコミュニケーションをとる準備をしている | O26: ● | P26: 1点：全社情報共有の会議への参加に向けた準備を計画している 2点：全社情報共有の会議へ班の代表として参加するための準備を計画をしている 3点：全社情報共有の会議で班の代表として参加するための準備を具体的に計画をしている ※班長代理の擁立、班の体制構築、収集情報のまとめ、班行動の計画、班間連携の計画
A27: 03総務 | B27: シーン2 | C27: 3 | D27: 個別 | E27: 個別 | F27: 発災当日21時 自班のTeamsチャット上で各拠点の被災状況が報告されました。 ・NTTドコモビジネスオフィスビルの被災状況として、事務室にモノが散乱しているエリア有 ・猿楽ビルの玄関が被災し通行止めの状況 ・大手町プレイスにて入室セキュリティシステムが一部停止 ・その他のビルはエレベータの稼働が3割程度 ・首都圏でビルに留まっているのは社員500名、委託業者320名、お客様55名 ・重傷者（本人、家族）、家屋の重被害ともに数名のまま増加なし あなたならどのような行動をとりますか？ 何を使用し、何を行うか具体的に記述して下さい。 ※評価対象コンピテンシー：コミュニケーション力、情報分析力、計画力 | G27: ● | H27: 1点：各組織総務厚生班への情報発信（一方向） 2点：各組織総務厚生班とコミュニケーションをとっている（双方向） 3点：班長不在の中でも班内の体制を構築した上で、各組織総務厚生班でコミュニケーションをとっている | K27: ● | L27: 1点：お客様、社員、委託業者など関係者への影響を確かめている 2点：お客様、社員、委託業者など関係者への重大な影響を及ぼす可能性がある因子を特定している 3点：お客様、社員、委託業者など関係者への重大な影響を及ぼす可能性がある因子を特定した上で、具体的な対応策の検討や災対本部などへ班間サポートを要請する等の行動を起こしている | O27: ● | P27: 1点：班内でできる被災状況への対応を検討している 2点：被災状況の分析結果に応じて、優先順位や適切な対応を具体的なに検討している 3点：被災状況の分析結果に応じて、災害対応の全体像を想定しながら、優先順位や適切な対応を先手先手で具体的に検討している
A28: 03総務 | B28: シーン2 | C28: 4 | D28: 個別 | E28: 個別 | F28: 発災翌日6時 地震発生から約12時間後の安否集計結果が、回答数7,520名。2.5割程度が本人・家族・家屋に被害発生。業務可能者は出社・リモートを含め5割程度。 班長とは未だ連絡が取れていません。勤務可能な社員が限られる一方で、安否不明者が多数います。 あなたならどのような行動をとりますか？ 何を使用し、何を行うか具体的に記述して下さい。 ※評価対象コンピテンシー：コミュニケーション力、情報収集力、想像・先読み力 | G28: ● | H28: 1点：各組織総務厚生班への情報発信（一方向） 2点：各組織総務厚生班とコミュニケーションをとっている（双方向） 3点：班長不在の中でも班内の体制を構築した上で、各組織総務厚生班でコミュニケーションをとっている | I28: ● | J28: 1点：自ら情報収集しようとしている 2点：指示をして各組織総務厚生班から安否不明者への対応状況や被害状況などの情報収集をしている 3点：班長不在の中でも班内の体制を構築した上で、先手先手で指示をして安否不明者への対応状況や被害状況などに関して災害対策本部などで班内外から情報収集している | M28: ● | N28: 1点：安否集計結果を元に次に起こる事を想定しようとしている 2点：安否集計結果を元に次に起こる事や自班やサービスへの影響を具体的に想像している 3点：安否集計結果を元に事態が改善や悪化することを先読みしながら自班やサービスへの影響を具体的に想像している
A29: 03総務 | B29: シーン2 | C29: 5 | D29: 個別 | E29: 個別 | F29: 発災翌日9時 自班のTeamsチャットで、首都圏内のNTTドコモビジネスオフィスビルのエントランス等へ一般の避難者が入り、ビルに留まっているとの情報が多く寄せられています。各ビルとも空調は稼働しているが、室温、照明等は省力稼働となっています。 あなたはどのような対応を計画しますか？ ※評価対象コンピテンシー：情報収集力、想像・先読み力、計画力 | I29: ● | J29: 1点：自ら情報収集しようとしている 2点：指示をして首都圏内のNTTドコモビジネスオフィスビルの状況の情報収集をしている 3点：避難者の心理面も含めて、今後の対応に必要な情報を先手先手で指示をして、災害対策本部など班内外から情報収集している | M29: ● | N29: 1点：次に起こる事を想定しようとしている 2点：次に起こる事を想定しつつ、必要な行動を具体的に検討している 3点：災害対応の全体プロセスを見据えて、次に起こる事を想定しつつ、必要な行動を具体的に検討している | O29: ● | P29: 1点：班内でできる対応を計画している 2点：班活動に必要な計画を立てている 3点：今後の状況を改善や悪化、現状維持など複数のシナリオを念頭に置きながら、具体的な計画を立てている
A30: 03総務 | B30: シーン2 | C30: 6 | D30: 個別 | E30: 個別 | F30: 発災翌日12時 自班のTeamsチャットへ情報が寄せられました。 ・NTTドコモビジネスオフィスビルでは、災対備蓄品を利用した食事を提供 ・自家発電の稼働によって、各ビル設備はほぼ通常運用中 ・首都圏以外の社員・パートナー社員の被災はほぼ無く、ほとんどが業務可能 ・首都圏へ出張中の社員の一部が帰宅出来ていない あなたならどのような行動をとりますか？ 何を使用し、何を行うか具体的に記述して下さい。 ※評価対象コンピテンシー：コミュニケーション力、想像・先読み力、計画力 | G30: ● | H30: 1点：各組織総務厚生班や帰宅困難社員の所属組織と連絡をとろうとしている 2点：各組織総務厚生班や帰宅困難社員の所属組織と双方向でコミュニケーションをとっている 3点：各組織総務厚生班や帰宅困難社員の所属組織と双方向でコミュニケーションをとることに加え、班長不在の中でも班内の体制を構築した上で、全社情報共有会議での報告や危機管理DBへの投入など、班外へも情報を共有し、コミュニケーションの活性化を行う | M30: ● | N30: 1点：次に起こる事を想定しようとしている 2点：次に起こる事を想定しつつ、必要な行動を具体的に検討している 3点：食事提供や帰宅困難社員に対して、災害対応の全体プロセスを見据えて、次に起こる事を想定しつつ、必要な行動を具体的に検討している | O30: ● | P30: 1点：班内でできる対応を計画している 2点：食事提供や帰宅困難社員に対応の計画を立てている 3点：今後の状況を改善や悪化、現状維持など複数のシナリオを念頭に置きながら、食事提供や帰宅困難社員対応の具体的な計画を立てている
A31: 03総務 | B31: シーン2 | C31: 7 | D31: 共通11 | E31: 共通 | F31: 発災翌日15時 班長と連絡が取れました。 あなたならどのような行動をとりますか？ 何を使用し、何を行うか具体的に記述して下さい。 ※評価対象コンピテンシー：コミュニケーション力 | G31: ● | H31: 1点：班長への情報提供（一方向） 2点：班長へのこれまでの対応事項や課題感に関するコミュニケーションをとっている（双方向） 3点：班長と双方向とのコミュニケーションに加えて、全社情報共有会議での報告や危機管理DBへの投入など、班外へも情報を共有し、コミュニケーションの活性化を行う
A32: 04サービス | B32: シーン2 | C32: 1 | D32: 共通09 | E32: 共通 | F32: 発災当日20時 引き続き、ネットは繋がるが、携帯電話は輻輳中で繋がりにくい状況です。班員とは連絡がとれましたが、班長と連絡が取れません。 あなたならどのような行動をとりますか？ 何を使用し、何を行うか具体的に記述して下さい。 ※評価対象コンピテンシー：コミュニケーション力、情報収集力 | G32: ● | H32: 1点：班員への情報発信（一方向） 2点：自班内でコミュニケーションをとろうとしている（双方向） 3点：班長代理や副班長を中心とした体制を構築した上で、班間、班内でコミュニケーションをとろうとしている | I32: ● | J32: 1点：班長への連絡を試みている、班員から情報を収集している 2点：SNS等を含めて複数の手段を活用して班長への連絡を試みている 現時点での班内のとりまとめに必要な情報を特定した上で班員から情報収集している 3点：班長への連絡の試みや班員からの情報収集に加えて、情報統括班への支援依頼や体制構築などを行っている
A33: 04サービス | B33: シーン2 | C33: 2 | D33: 共通10 | E33: 共通 | F33: 発災当日21時 西日本初動本部より、22時から全社情報共有の会議を実施する連絡が入りました。班長不在の中、会議開始までの1時間で班としてやるべきことを検討して下さい。 ※評価対象コンピテンシー：コミュニケーション力、計画力 | G33: ● | H33: 1点：班員への情報発信（一方向） 2点：班長と連絡をとり続けるとともに、全社情報共有の会議参加に向けて、自班内でコミュニケーションをとっている（双方向） 3点：班長と連絡をとり続けるとともに、班長代理や副班長を中心とした体制を構築した上で、班間、班内でコミュニケーションをとる準備をしている | O33: ● | P33: 1点：全社情報共有の会議への参加に向けた準備を計画している 2点：全社情報共有の会議へ班の代表として参加するための準備を計画をしている 3点：全社情報共有の会議で班の代表として参加するための準備を具体的に計画をしている ※班長代理の擁立、班の体制構築、収集情報のまとめ、班行動の計画、班間連携の計画
A34: 04サービス | B34: シーン2 | C34: 3 | D34: 個別 | E34: 個別 | F34: 発災当日21時 ドコモ代理サービスに影響が出ているらしいとサービス主管部門（5GIoTの担当者）からTeamsチャットで報告を受けました。 あなたならどのような行動をとりますか？ 何を使用し、何を行うか具体的に記述して下さい。 ※評価対象コンピテンシー：コミュニケーション力、情報収集力 | G34: ● | H34: 1点：サービス主管部門と連絡をとうろうとしている（情報収集） 2点：サービス主管部門とのコミュニケーション窓口となって情報をコントロールしている 3点：サービス主管部門とのコミュニケーション窓口となり班間の情報をコントロールし、当該代理サービス並びに代理サービスの影響については、ドコモ側の緊急体制Lv1/Lv2会議の開催状況を確認しようとしている、または情報統括班へ依頼してドコモから情報収集している | I34: ● | J34: 1点：自らサービス主管門から情報収集している 2点：指示をして班内の各サービス主幹部門から情報収集している 3点：指示をして班内の各サービス主幹部門から情報収集するとともに、当該代理サービス並びに代理サービスの影響については、ドコモ側の緊急体制Lv1/Lv2会議の開催状況を確認しようとしている、または情報統括班へ依頼してドコモから情報収集している
A35: 04サービス | B35: シーン2 | C35: 4 | D35: 個別 | E35: 個別 | F35: 発災当日21時 携帯電話サービスに影響が出ているという情報を危機管理DB「ドコモ災対」タブで確認しました。非常態勢時において携帯サービスの影響確認をどのように行いますか？ ＜危機管理DBの記載内容＞ ◆輻輳規制地域情報 ・アクセス％規制：CS10% ・SSAC規制：50% ・着CA規制（3G/LTE）：90% ・固定向け電番規制（東京、千葉、神奈川、埼玉向け）：75% ◆基地局被害状況 ・サービス中断835（東京231、千葉121、神奈川267、埼玉216） ・停電1,750（東京602、千葉289、神奈川464、埼玉395） ※評価対象コンピテンシー：情報分析力、想像・先読み力 | K35: ● | L35: 1点：危機管理DBの情報を分析して、サービス影響を把握しようとしている 2点：危機管理DBの情報を分析して、サービス影響を及ぼす可能性がある因子の特定している 3点：危機管理DBの情報を分析して、重大なサービス影響を及ぼす可能性がある因子を特定した上で、災害対策本部など、班間でのサポートを要請（注意喚起）する等の行動に活かしている | M35: ● | N35: 1点：次に起こる事を想定しようとしている 2点：次に起こる事を想定しつつ、必要な行動を具体的に検討している 3点：サービス影響の悪化や改善を想定しながら、災害対応の全体プロセスを見据えて、次に起こる事を想定しつつ、必要な行動を具体的に検討している
A36: 04サービス | B36: シーン2 | C36: 5 | D36: 個別 | E36: 個別 | F36: 発災当日22時 全社情報共有の会議にて設備班より中央第二光（新立川別～新宿別）ケーブル断情報が共有されました。 あなたならどのような行動をとりますか？ 何を使用し、何を行うか具体的に記述して下さい。 ※評価対象コンピテンシー：コミュニケーション力、情報分析力、想像・先読み力 | G36: ● | H36: 1点：設備班と連絡をとろうとしている 2点：設備班やサービス影響に関連する班内メンバと双方向でコミュニケーションをとっている 3点：班長不在の中でも班内の体制を構築した上で、サービス影響の把握や今後の対応に向けて必要な班内外との双方向コミュニケーションをとっている | K36: ● | L36: 1点：サービスへの影響を確認している 2点：サービスへの重大な影響を及ぼす可能性がある因子を特定している 3点：自班やサービスへの重大な影響を及ぼす可能性がある因子を特定した上で、災対本部など、班間でのサポートを要請（注意喚起）する等の行動を起こしている | M36: ● | N36: 1点：次に起こる事を想定しようとしている 2点：次に起こる事を想定しつつ、必要な行動を具体的に検討している 3点：サービス影響の悪化や改善を想定しながら、災害対応の全体プロセスを見据えて、次に起こる事を想定しつつ、事前対策等、必要な行動を具体的に検討している
A37: 04サービス | B37: シーン2 | C37: 6 | D37: 個別 | E37: 個別 | F37: 発災翌日12時 全社情報共有の会議で設備班から以下の情報が流れて来ました。 ・唐ヶ崎、白鬚、千葉港、一ツ橋ビル停電発生 ※一ツ橋は30分で復電 ・電力・空調設備は異常なし（エンジン運転中） あなたならどのような行動をとりますか？ 何を使用し、何を行うか具体的に記述して下さい。 ※評価対象コンピテンシー：情報分析力、想像・先読み力 | K37: ● | L37: 1点：サービスへの影響を確認している 2点：サービスへの重大な影響を及ぼす可能性がある因子（燃料切れ）を特定している 3点：自班やサービスへの重大な影響を及ぼす可能性がある因子（燃料切れ）を特定した上で、最悪の事態に対応するための行動を起こしている | M37: ● | N37: 1点：次に起こる事を想定しようとしている 2点：次に起こる事（燃料切れ）を想定しつつ、必要な行動を具体的に検討している 3点：事態の悪化（燃料切れ）を想定しながら、災害対応の全体プロセスを見据えて、対応策や事前対策等、必要な行動を具体的に検討している
A38: 04サービス | B38: シーン2 | C38: 7 | D38: 共通11 | E38: 共通 | F38: 発災翌日15時 班長と連絡が取れました。 あなたならどのような行動をとりますか？ 何を使用し、何を行うか具体的に記述して下さい。 ※評価対象コンピテンシー：コミュニケーション力 | G38: ● | H38: 1点：班長への情報提供（一方向） 2点：班長へのこれまでの対応事項や課題感に関するコミュニケーションをとっている（双方向） 3点：班長と双方向とのコミュニケーションに加えて、全社情報共有会議での報告や危機管理DBへの投入など、班外へも情報を共有し、コミュニケーションの活性化を行う
A39: 05お客様対応 | B39: シーン2 | C39: 1 | D39: 共通09 | E39: 共通 | F39: 発災当日20時 引き続き、ネットは繋がるが、携帯電話は輻輳中で繋がりにくい状況です。班員とは連絡がとれましたが、班長と連絡が取れません。 あなたならどのような行動をとりますか？ 何を使用し、何を行うか具体的に記述して下さい。 ※評価対象コンピテンシー：コミュニケーション力、情報収集力 | G39: ● | H39: 1点：班員への情報発信（一方向） 2点：自班内でコミュニケーションをとろうとしている（双方向） 3点：班長代理や副班長を中心とした体制を構築した上で、班間、班内でコミュニケーションをとろうとしている | I39: ● | J39: 1点：班長への連絡を試みている、班員から情報を収集している 2点：SNS等を含めて複数の手段を活用して班長への連絡を試みている 現時点での班内のとりまとめに必要な情報を特定した上で班員から情報収集している 3点：班長への連絡の試みや班員からの情報収集に加えて、情報統括班への支援依頼や体制構築などを行っている
A40: 05お客様対応 | B40: シーン2 | C40: 2 | D40: 共通10 | E40: 共通 | F40: 発災当日21時 西日本初動本部より、22時から全社情報共有の会議を実施する連絡が入りました。班長不在の中、会議開始までの1時間で班としてやるべきことを検討して下さい。 ※評価対象コンピテンシー：コミュニケーション力、計画力 | G40: ● | H40: 1点：班員への情報発信（一方向） 2点：班長と連絡をとり続けるとともに、全社情報共有の会議参加に向けて、自班内でコミュニケーションをとっている（双方向） 3点：班長と連絡をとり続けるとともに、班長代理や副班長を中心とした体制を構築した上で、班間、班内でコミュニケーションをとる準備をしている | O40: ● | P40: 1点：全社情報共有の会議への参加に向けた準備を計画している 2点：全社情報共有の会議へ班の代表として参加するための準備を計画をしている 3点：全社情報共有の会議で班の代表として参加するための準備を具体的に計画をしている ※班長代理の擁立、班の体制構築、収集情報のまとめ、班行動の計画、班間連携の計画
A41: 05お客様対応 | B41: シーン2 | C41: 3 | D41: 個別 | E41: 個別 | F41: 発災当日21時 「自身の所属組織は非被災地であるにも関わらず、被災直後に被災エリアに拠点を持つお客様からの問い合わせが複数発生した」との連絡が全社情報共有の会議参加の営業担当者から入ってきました。お客様対応班の事務局メンバーは不在です。 あなたならどのような行動を行いますか？ 何を使用し、何を行うか具体的に記述して下さい。 ※評価対象コンピテンシー：コミュニケーション力、情報収集力 | G41: ● | H41: ≪コミュニケーション力≫ ・求められた意見に対して自身の経験や知識をもとにアドバイス １点 ・その他の同様の問合せや依頼が来ていることも想定し、貸出物品に関する情報展開と情報収集を実施 ２点 ・貸出物品にとどまらず、潜在的なニーズも意識して情報を聞き出す・収集する行動を実施 ３点 | I41: ● | J41: ≪情報収集力≫ ・自身の判断でなんとか対応しようとする １点 ・まず記録に残す 1点 ・班内への情報展開と情報収集によって、よりよい対応に努める ２点 ・非被災地のどんなエリアからの情報か収集する 2点 ・班をまたがる情報収集、展開を行い、より効率的な活動を行う ３点 ・非被災地のお客さまの要望を把握し、広報的な情報発信を提案する 3
...

Sheet コンピテンシー
A1: シーン1 | R1: シーン | S1: シーン1 | AF1: シーン | AG1: シーン2 | AT1: シーン | AU1: シーン3
B2: ｺﾐｭﾆｹｰｼｮﾝ | E2: 情報収集 | H2: 情報分析 | K2: 想像・先読み | N2: 計画 | R2: 共／個 | S2: 共通 | AF2: 共／個 | AG2: 共通 | AT2: 共／個 | AU2: 共通
B3: 共通 | C3: 個別 | D3: 計 | E3: 共通 | F3: 個別 | G3: 計 | H3: 共通 | I3: 個別 | J3: 計 | K3: 共通 | L3: 個別 | M3: 計 | N3: 共通 | O3: 個別 | P3: 計
A4: 01本部長支援 | B4: =$Z$5 -> 0 | C4: 0 | D4: =SUM(B4:C4) -> 0 | E4: =$AA$5 -> 6 | F4: 0 | G4: =SUM(E4:F4) -> 6 | H4: =$AB$5 -> 3 | I4: 0 | J4: =SUM(H4:I4) -> 3 | K4: =$AC$5 -> 4 | L4: 0 | M4: =SUM(K4:L4) -> 4 | N4: =$AD$5 -> 4 | O4: 0 | P4: =SUM(N4:O4) -> 4 | R4: 行ラベル | S4: 個数 / ｺﾐｭﾆｹｰｼｮﾝ | T4: 個数 / 情報収集 | U4: 個数 / 情報分析 | V4: 個数 / 想像・先読み | W4: 個数 / 計画 | Y4: 行ラベル | Z4: 個数 / ｺﾐｭﾆｹｰｼｮﾝ | AA4: 個数 / 情報収集 | AB4: 個数 / 情報分析 | AC4: 個数 / 想像・先読み | AD4: 個数 / 計画 | AF4: 行ラベル | AG4: 個数 / ｺﾐｭﾆｹｰｼｮﾝ | AH4: 個数 / 情報収集 | AI4: 個数 / 情報分析 | AJ4: 個数 / 想像・先読み | AK4: 個数 / 計画 | AM4: 行ラベル | AN4: 個数 / ｺﾐｭﾆｹｰｼｮﾝ | AO4: 個数 / 情報収集 | AP4: 個数 / 情報分析 | AQ4: 個数 / 想像・先読み | AR4: 個数 / 計画 | AT4: 行ラベル | AU4: 個数 / ｺﾐｭﾆｹｰｼｮﾝ | AV4: 個数 / 情報収集 | AW4: 個数 / 情報分析 | AX4: 個数 / 想像・先読み | AY4: 個数 / 計画 | BA4: 行ラベル | BB4: 個数 / ｺﾐｭﾆｹｰｼｮﾝ | BC4: 個数 / 情報収集 | BD4: 個数 / 情報分析 | BE4: 個数 / 想像・先読み | BF4: 個数 / 計画
A5: 02広報 | B5: =$Z$5 -> 0 | C5: 0 | D5: 0 | E5: =$AA$5 -> 6 | F5: 0 | G5: =SUM(E5:F5) -> 6 | H5: =$AB$5 -> 3 | I5: 0 | J5: =SUM(H5:I5) -> 3 | K5: =$AC$5 -> 4 | L5: 0 | M5: =SUM(K5:L5) -> 4 | N5: =$AD$5 -> 4 | O5: 0 | P5: =SUM(N5:O5) -> 4 | R5: 00全班共通 | T5: 6 | U5: 3 | V5: 4 | W5: 4 | Y5: 00全班共通 | AA5: 6 | AB5: 3 | AC5: 4 | AD5: 4 | AF5: 01本部長支援 | AG5: 3 | AH5: 1 | AK5: 1 | AM5: 01本部長支援 | AN5: 3 | AO5: 1 | AR5: 1 | AT5: 01本部長支援 | AU5: 2 | AV5: 1 | AW5: 1 | AX5: 1 | AY5: 3 | BA5: 01本部長支援 | BB5: 2 | BC5: 1 | BD5: 1 | BE5: 1 | BF5: 3
A6: 03総務 | B6: =$Z$5 -> 0 | C6: 0 | D6: 0 | E6: =$AA$5 -> 6 | F6: 0 | G6: =SUM(E6:F6) -> 6 | H6: =$AB$5 -> 3 | I6: 0 | J6: =SUM(H6:I6) -> 3 | K6: =$AC$5 -> 4 | L6: 0 | M6: =SUM(K6:L6) -> 4 | N6: =$AD$5 -> 4 | O6: 0 | P6: =SUM(N6:O6) -> 4 | R6: 総計 | T6: 6 | U6: 3 | V6: 4 | W6: 4 | Y6: 総計 | AA6: 6 | AB6: 3 | AC6: 4 | AD6: 4 | AF6: 02広報 | AG6: 3 | AH6: 1 | AK6: 1 | AM6: 02広報 | AN6: 3 | AO6: 1 | AR6: 1 | AT6: 02広報 | AU6: 2 | AV6: 1 | AW6: 1 | AX6: 1 | AY6: 3 | BA6: 02広報 | BB6: 2 | BC6: 1 | BD6: 1 | BE6: 1 | BF6: 3
A7: 04サービス | B7: =$Z$5 -> 0 | C7: 0 | D7: 0 | E7: =$AA$5 -> 6 | F7: 0 | G7: =SUM(E7:F7) -> 6 | H7: =$AB$5 -> 3 | I7: 0 | J7: =SUM(H7:I7) -> 3 | K7: =$AC$5 -> 4 | L7: 0 | M7: =SUM(K7:L7) -> 4 | N7: =$AD$5 -> 4 | O7: 0 | P7: =SUM(N7:O7) -> 4 | AF7: 03総務 | AG7: 3 | AH7: 1 | AK7: 1 | AM7: 03総務 | AN7: 3 | AO7: 1 | AR7: 1 | AT7: 03総務 | AU7: 2 | AV7: 1 | AW7: 1 | AX7: 1 | AY7: 3 | BA7: 03総務 | BB7: 2 | BC7: 1 | BD7: 1 | BE7: 1 | BF7: 3
A8: 05お客様対応 | B8: =$Z$5 -> 0 | C8: 0 | D8: 0 | E8: =$AA$5 -> 6 | F8: 0 | G8: =SUM(E8:F8) -> 6 | H8: =$AB$5 -> 3 | I8: 0 | J8: =SUM(H8:I8) -> 3 | K8: =$AC$5 -> 4 | L8: 0 | M8: =SUM(K8:L8) -> 4 | N8: =$AD$5 -> 4 | O8: 0 | P8: =SUM(N8:O8) -> 4 | AF8: 04サービス | AG8: 3 | AH8: 1 | AK8: 1 | AM8: 04サービス | AN8: 3 | AO8: 1 | AR8: 1 | AT8: 04サービス | AU8: 2 | AV8: 1 | AW8: 1 | AX8: 1 | AY8: 3 | BA8: 04サービス | BB8: 2 | BC8: 1 | BD8: 1 | BE8: 1 | BF8: 3
A9: 06設備 | B9: =$Z$5 -> 0 | C9: 0 | D9: 0 | E9: =$AA$5 -> 6 | F9: 0 | G9: =SUM(E9:F9) -> 6 | H9: =$AB$5 -> 3 | I9: 0 | J9: =SUM(H9:I9) -> 3 | K9: =$AC$5 -> 4 | L9: 0 | M9: =SUM(K9:L9) -> 4 | N9: =$AD$5 -> 4 | O9: 0 | P9: =SUM(N9:O9) -> 4 | AF9: 05お客様対応 | AG9: 3 | AH9: 1 | AK9: 1 | AM9: 05お客様対応 | AN9: 3 | AO9: 1 | AR9: 1 | AT9: 05お客様対応 | AU9: 2 | AV9: 1 | AW9: 1 | AX9: 1 | AY9: 3 | BA9: 05お客様対応 | BB9: 2 | BC9: 1 | BD9: 1 | BE9: 1 | BF9: 3
A10: 07資材 | B10: =$Z$5 -> 0 | C10: 0 | D10: 0 | E10: =$AA$5 -> 6 | F10: 0 | G10: =SUM(E10:F10) -> 6 | H10: =$AB$5 -> 3 | I10: 0 | J10: =SUM(H10:I10) -> 3 | K10: =$AC$5 -> 4 | L10: 0 | M10: =SUM(K10:L10) -> 4 | N10: =$AD$5 -> 4 | O10: 0 | P10: =SUM(N10:O10) -> 4 | AF10: 06設備 | AG10: 3 | AH10: 1 | AK10: 1 | AM10: 06設備 | AN10: 3 | AO10: 1 | AR10: 1 | AT10: 06設備 | AU10: 2 | AV10: 1 | AW10: 1 | AX10: 1 | AY10: 3 | BA10: 06設備 | BB10: 2 | BC10: 1 | BD10: 1 | BE10: 1 | BF10: 3
A11: 08セキュリティ | B11: =$Z$5 -> 0 | C11: 0 | D11: 0 | E11: =$AA$5 -> 6 | F11: 0 | G11: =SUM(E11:F11) -> 6 | H11: =$AB$5 -> 3 | I11: 0 | J11: =SUM(H11:I11) -> 3 | K11: =$AC$5 -> 4 | L11: 0 | M11: =SUM(K11:L11) -> 4 | N11: =$AD$5 -> 4 | O11: 0 | P11: =SUM(N11:O11) -> 4 | AF11: 07資材 | AG11: 3 | AH11: 1 | AK11: 1 | AM11: 07資材 | AN11: 3 | AO11: 1 | AR11: 1 | AT11: 07資材 | AU11: 2 | AV11: 1 | AW11: 1 | AX11: 1 | AY11: 3 | BA11: 07資材 | BB11: 2 | BC11: 1 | BD11: 1 | BE11: 1 | BF11: 3
A12: 09社内システム | B12: =$Z$5 -> 0 | C12: 0 | D12: 0 | E12: =$AA$5 -> 6 | F12: 0 | G12: =SUM(E12:F12) -> 6 | H12: =$AB$5 -> 3 | I12: 0 | J12: =SUM(H12:I12) -> 3 | K12: =$AC$5 -> 4 | L12: 0 | M12: =SUM(K12:L12) -> 4 | N12: =$AD$5 -> 4 | O12: 0 | P12: =SUM(N12:O12) -> 4 | AF12: 08セキュリティ | AG12: 3 | AH12: 1 | AK12: 1 | AM12: 08セキュリティ | AN12: 3 | AO12: 1 | AR12: 1 | AT12: 08セキュリティ | AU12: 2 | AV12: 1 | AW12: 1 | AX12: 1 | AY12: 3 | BA12: 08セキュリティ | BB12: 2 | BC12: 1 | BD12: 1 | BE12: 1 | BF12: 3
A13: 10情報統括 | B13: =$Z$5 -> 0 | C13: 0 | D13: 0 | E13: =$AA$5 -> 6 | F13: 0 | G13: =SUM(E13:F13) -> 6 | H13: =$AB$5 -> 3 | I13: 0 | J13: =SUM(H13:I13) -> 3 | K13: =$AC$5 -> 4 | L13: 0 | M13: =SUM(K13:L13) -> 4 | N13: =$AD$5 -> 4 | O13: 0 | P13: =SUM(N13:O13) -> 4 | AF13: 09社内システム | AG13: 3 | AH13: 1 | AK13: 1 | AM13: 09社内システム | AN13: 3 | AO13: 1 | AR13: 1 | AT13: 09社内システム | AU13: 2 | AV13: 1 | AW13: 1 | AX13: 1 | AY13: 3 | BA13: 09社内システム | BB13: 2 | BC13: 1 | BD13: 1 | BE13: 1 | BF13: 3
A14: 計 | D14: =SUM(D4:D13) -> 0 | G14: =SUM(G4:G13) -> 60 | J14: =SUM(J4:J13) -> 30 | M14: =SUM(M4:M13) -> 40 | P14: =SUM(P4:P13) -> 40 | AF14: 10情報統括 | AG14: 3 | AH14: 1 | AK14: 1 | AM14: 10情報統括 | AN14: 3 | AO14: 1 | AR14: 1 | AT14: 10情報統括 | AU14: 2 | AV14: 1 | AW14: 1 | AX14: 1 | AY14: 3 | BA14: 10情報統括 | BB14: 2 | BC14: 1 | BD14: 1 | BE14: 1 | BF14: 3
AF15: 総計 | AG15: 30 | AH15: 10 | AK15: 10 | AM15: 総計 | AN15: 30 | AO15: 10 | AR15: 10 | AT15: 総計 | AU15: 20 | AV15: 10 | AW15: 10 | AX15: 10 | AY15: 30 | BA15: 総計 | BB15: 20 | BC15: 10 | BD15: 10 | BE15: 10 | BF15: 30
A16: シーン2
B17: ｺﾐｭﾆｹｰｼｮﾝ | E17: 情報収集 | H17: 情報分析 | K17: 想像・先読み | N17: 計画 | AF17: シーン | AG17: シーン2 | AT17: シーン | AU17: シーン3
B18: 共通 | C18: 個別 | D18: 計 | E18: 共通 | F18: 個別 | G18: 計 | H18: 共通 | I18: 個別 | J18: 計 | K18: 共通 | L18: 個別 | M18: 計 | N18: 共通 | O18: 個別 | P18: 計 | AF18: 共／個 | AG18: 個別 | AT18: 共／個 | AU18: 個別
A19: 01本部長支援 | B19: =AN5 -> 3 | C19: =AN21 -> 3 | D19: =SUM(B19:C19) -> 6 | E19: =AO5 -> 1 | F19: =AO21 -> 2 | G19: =SUM(E19:F19) -> 3 | H19: =AP5 -> 0 | I19: =AP21 -> 1 | J19: =SUM(H19:I19) -> 1 | K19: =AQ5 -> 0 | L19: =AQ21 -> 1 | M19: =SUM(K19:L19) -> 1 | N19: =AR5 -> 1 | O19: =AR21 -> 2 | P19: =SUM(N19:O19) -> 3
A20: 02広報 | B20: =AN6 -> 3 | C20: =AN22 -> 1 | D20: =SUM(B20:C20) -> 4 | E20: =AO6 -> 1 | F20: =AO22 -> 2 | G20: =SUM(E20:F20) -> 3 | H20: =AP6 -> 0 | I20: =AP22 -> 1 | J20: =SUM(H20:I20) -> 1 | K20: =AQ6 -> 0 | L20: =AQ22 -> 1 | M20: =SUM(K20:L20) -> 1 | N20: =AR6 -> 1 | O20: =AR22 -> 2 | P20: =SUM(N20:O20) -> 3 | AF20: 行ラベル | AG20: 個数 / ｺﾐｭﾆｹｰｼｮﾝ | AH20: 個数 / 情報収集 | AI20: 個数 / 情報分析 | AJ20: 個数 / 想像・先読み | AK20: 個数 / 計画 | AM20: 行ラベル | AN20: 個数 / ｺﾐｭﾆｹｰｼｮﾝ | AO20: 個数 / 情報収集 | AP20: 個数 / 情報分析 | AQ20: 個数 / 想像・先読み | AR20: 個数 / 計画 | AT20: 行ラベル | AU20: 個数 / ｺﾐｭﾆｹｰｼｮﾝ | AV20: 個数 / 情報収集 | AW20: 個数 / 情報分析 | AX20: 個数 / 想像・先読み | AY20: 個数 / 計画 | BA20: 行ラベル | BB20: 個数 / ｺﾐｭﾆｹｰｼｮﾝ | BC20: 個数 / 情報収集 | BD20: 個数 / 情報分析 | BE20: 個数 / 想像・先読み | BF20: 個数 / 計画
A21: 03総務 | B21: =AN7 -> 3 | C21: =AN23 -> 3 | D21: =SUM(B21:C21) -> 6 | E21: =AO7 -> 1 | F21: =AO23 -> 2 | G21: =SUM(E21:F21) -> 3 | H21: =AP7 -> 0 | I21: =AP23 -> 1 | J21: =SUM(H21:I21) -> 1 | K21: =AQ7 -> 0 | L21: =AQ23 -> 3 | M21: =SUM(K21:L21) -> 3 | N21: =AR7 -> 1 | O21: =AR23 -> 3 | P21: =SUM(N21:O21) -> 4 | AF21: 01本部長支援 | AG21: 3 | AH21: 2 | AI21: 1 | AJ21: 1 | AK21: 2 | AM21: 01本部長支援 | AN21: 3 | AO21: 2 | AP21: 1 | AQ21: 1 | AR21: 2 | AT21: 01本部長支援 | AU21: 2 | AV21: 2 | AW21: 1 | AX21: 1 | AY21: 2 | BA21: 01本部長支援 | BB21: 2 | BC21: 2 | BD21: 1 | BE21: 1 | BF21: 2
A22: 04サービス | B22: =AN8 -> 3 | C22: =AN24 -> 2 | D22: =SUM(B22:C22) -> 5 | E22: =AO8 -> 1 | F22: =AO24 -> 1 | G22: =SUM(E22:F22) -> 2 | H22: =AP8 -> 0 | I22: =AP24 -> 3 | J22: =SUM(H22:I22) -> 3 | K22: =AQ8 -> 0 | L22: =AQ24 -> 3 | M22: =SUM(K22:L22) -> 3 | N22: =AR8 -> 1 | O22: =AR24 -> 0 | P22: =SUM(N22:O22) -> 1 | AF22: 02広報 | AG22: 1 | AH22: 2 | AI22: 1 | AJ22: 1 | AK22: 2 | AM22: 02広報 | AN22: 1 | AO22: 2 | AP22: 1 | AQ22: 1 | AR22: 2 | AT22: 02広報 | AU22: 3 | AW22: 1 | AY22: 3 | BA22: 02広報 | BB22: 3 | BD22: 1 | BF22: 3
A23: 05お客様対応 | B23: =AN9 -> 3 | C23: =AN25 -> 3 | D23: =SUM(B23:C23) -> 6 | E23: =AO9 -> 1 | F23: =AO25 -> 3 | G23: =SUM(E23:F23) -> 4 | H23: =AP9 -> 0 | I23: =AP25 -> 0 | J23: =SUM(H23:I23) -> 0 | K23: =AQ9 -> 0 | L23: =AQ25 -> 0 | M23: =SUM(K23:L23) -> 0 | N23: =AR9 -> 1 | O23: =AR25 -> 1 | P23: =SUM(N23:O23) -> 2 | AF23: 03総務 | AG23: 3 | AH23: 2 | AI23: 1 | AJ23: 3 | AK23: 3 | AM23: 03総務 | AN23: 3 | AO23: 2 | AP23: 1 | AQ23: 3 | AR23: 3 | AT23: 03総務 | AU23: 3 | AW23: 1 | AX23: 2 | AY23: 4 | BA23: 03総務 | BB23: 3 | BD23: 1 | BE23: 2 | BF23: 4
A24: 06設備 | B24: =AN10 -> 3 | C24: =AN26 -> 2 | D24: =SUM(B24:C24) -> 5 | E24: =AO10 -> 1 | F24: =AO26 -> 2 | G24: =SUM(E24:F24) -> 3 | H24: =AP10 -> 0 | I24: =AP26 -> 1 | J24: =SUM(H24:I24) -> 1 | K24: =AQ10 -> 0 | L24: =AQ26 -> 1 | M24: =SUM(K24:L24) -> 1 | N24: =AR10 -> 1 | O24: =AR26 -> 4 | P24: =SUM(N24:O24) -> 5 | AF24: 04サービス | AG24: 2 | AH24: 1 | AI24: 3 | AJ24: 3 | AM24: 04サービス | AN24: 2 | AO24: 1 | AP24: 3 | AQ24: 3 | AT24: 04サービス | AU24: 2 | AV24: 3 | AW24: 1 | AX24: 1 | AY24: 1 | BA24: 04サービス | BB24: 2 | BC24: 3 | BD24: 1 | BE24: 1 | BF24: 1
A25: 07資材 | B25: =AN11 -> 3 | C25: =AN27 -> 2 | D25: =SUM(B25:C25) -> 5 | E25: =AO11 -> 1 | F25: =AO27 -> 2 | G25: =SUM(E25:F25) -> 3 | H25: =AP11 -> 0 | I25: =AP27 -> 1 | J25: =SUM(H25:I25) -> 1 | K25: =AQ11 -> 0 | L25: =AQ27 -> 1 | M25: =SUM(K25:L25) -> 1 | N25: =AR11 -> 1 | O25: =AR27 -> 3 | P25: =SUM(N25:O25) -> 4 | AF25: 05お客様対応 | AG25: 3 | AH25: 3 | AK25: 1 | AM25: 05お客様対応 | AN25: 3 | AO25: 3 | AR25: 1 | AT25: 05お客様対応 | AV25: 3 | AW25: 1 | AY25: 2 | BA25: 05お客様対応 | BC25: 3 | BD25: 1 | BF25: 2
A26: 08セキュリティ | B26: =AN12 -> 3 | C26: =AN28 -> 0 | D26: =SUM(B26:C26) -> 3 | E26: =AO12 -> 1 | F26: =AO28 -> 2 | G26: =SUM(E26:F26) -> 3 | H26: =AP12 -> 0 | I26: =AP28 -> 0 | J26: =SUM(H26:I26) -> 0 | K26: =AQ12 -> 0 | L26: =AQ28 -> 2 | M26: =SUM(K26:L26) -> 2 | N26: =AR12 -> 1 | O26: =AR28 -> 4 | P26: =SUM(N26:O26) -> 5 | AF26: 06設備 | AG26: 2 | AH26: 2 | AI26: 1 | AJ26: 1 | AK26: 4 | AM26: 06設備 | AN26: 2 | AO26: 2 | AP26: 1 | AQ26: 1 | AR26: 4 | AT26: 06設備 | AU26: 1 | AV26: 1 | AX26: 3 | AY26: 4 | BA26: 06設備 | BB26: 1 | BC26: 1 | BE26: 3 | BF26: 4
A27: 09社内システム | B27: =AN13 -> 3 | C27: =AN29 -> 0 | D27: =SUM(B27:C27) -> 3 | E27: =AO13 -> 1 | F27: =AO29 -> 3 | G27: =SUM(E27:F27) -> 4 | H27: =AP13 -> 0 | I27: =AP29 -> 1 | J27: =SUM(H27:I27) -> 1 | K27: =AQ13 -> 0 | L27: =AQ29 -> 0 | M27: =SUM(K27:L27) -> 0 | N27: =AR13 -> 1 | O27: =AR29 -> 3 | P27: =SUM(N27:O27) -> 4 | AF27: 07資材 | AG27: 2 | AH27: 2 | AI27: 1 | AJ27: 1 | AK27: 3 | AM27: 07資材 | AN27: 2 | AO27: 2 | AP27: 1 | AQ27: 1 | AR27: 3 | AT27: 07資材 | AU27: 3 | AV27: 1 | AY27: 4 | BA27: 07資材 | BB27: 3 | BC27: 1 | BF27: 4
A28: 10情報統括 | B28: =AN14 -> 3 | C28: =AN30 -> 2 | D28: =SUM(B28:C28) -> 5 | E28: =AO14 -> 1 | F28: =AO30 -> 1 | G28: =SUM(E28:F28) -> 2 | H28: =AP14 -> 0 | I28: =AP30 -> 1 | J28: =SUM(H28:I28) -> 1 | K28: =AQ14 -> 0 | L28: =AQ30 -> 2 | M28: =SUM(K28:L28) -> 2 | N28: =AR14 -> 1 | O28: =AR30 -> 2 | P28: =SUM(N28:O28) -> 3 | AF28: 08セキュリティ | AH28: 2 | AJ28: 2 | AK28: 4 | AM28: 08セキュリティ | AO28: 2 | AQ28: 2 | AR28: 4 | AT28: 08セキュリティ | AW28: 2 | AX28: 1 | AY28: 4 | BA28: 08セキュリティ | BD28: 2 | BE28: 1 | BF28: 4
A29: 計 | D29: =SUM(D19:D28) -> 48 | G29: =SUM(G19:G28) -> 30 | J29: =SUM(J19:J28) -> 10 | M29: =SUM(M19:M28) -> 14 | P29: =SUM(P19:P28) -> 34 | AF29: 09社内システム | AH29: 3 | AI29: 1 | AK29: 3 | AM29: 09社内システム | AO29: 3 | AP29: 1 | AR29: 3 | AT29: 09社内システム | AV29: 2 | AY29: 2 | BA29: 09社内システム | BC29: 2 | BF29: 2
AF30: 10情報統括 | AG30: 2 | AH30: 1 | AI30: 1 | AJ30: 2 | AK30: 2 | AM30: 10情報統括 | AN30: 2 | AO30: 1 | AP30: 1 | AQ30: 2 | AR30: 2 | AT30: 10情報統括 | AU30: 4 | AV30: 3 | AW30: 1 | AX30: 2 | AY30: 3 | BA30: 10情報統括 | BB30: 4 | BC30: 3 | BD30: 1 | BE30: 2 | BF30: 3
A31: シーン3 | AF31: 総計 | AG31: 18 | AH31: 20 | AI31: 10 | AJ31: 14 | AK31: 24 | AM31: 総計 | AN31: 19 | AO31: 20 | AP31: 10 | AQ31: 14 | AR31: 24 | AT31: 総計 | AU31: 18 | AV31: 15 | AW31: 8 | AX31: 10 | AY31: 29 | BA31: 総計 | BB31: 18 | BC31: 15 | BD31: 8 | BE31: 10 | BF31: 29
B32: ｺﾐｭﾆｹｰｼｮﾝ | E32: 情報収集 | H32: 情報分析 | K32: 想像・先読み | N32: 計画
B33: 共通 | C33: 個別 | D33: 計 | E33: 共通 | F33: 個別 | G33: 計 | H33: 共通 | I33: 個別 | J33: 計 | K33: 共通 | L33: 個別 | M33: 計 | N33: 共通 | O33: 個別 | P33: 計
A34: 01本部長支援 | B34: =BB5 -> 2 | C34: =BB21 -> 2 | D34: =SUM(B34:C34) -> 4 | E34: =BC5 -> 1 | F34: =BC21 -> 2 | G34: =SUM(E34:F34) -> 3 | H34: =BD5 -> 1 | I34: =BD21 -> 1 | J34: =SUM(H34:I34) -> 2 | K34: =BE5 -> 1 | L34: =BE21 -> 1 | M34: =SUM(K34:L34) -> 2 | N34: =BF5 -> 3 | O34: =BF21 -> 2 | P34: =SUM(N34:O34) -> 5
A35: 02広報 | B35: =BB6 -> 2 | C35: =BB22 -> 3 | D35: =SUM(B35:C35) -> 5 | E35: =BC6 -> 1 | F35: =BC22 -> 0 | G35: =SUM(E35:F35) -> 1 | H35: =BD6 -> 1 | I35: =BD22 -> 1 | J35: =SUM(H35:I35) -> 2 | K35: =BE6 -> 1 | L35: =BE22 -> 0 | M35: =SUM(K35:L35) -> 1 | N35: =BF6 -> 3 | O35: =BF22 -> 3 | P35: =SUM(N35:O35) -> 6
A36: 03総務 | B36: =BB7 -> 2 | C36: =BB23 -> 3 | D36: =SUM(B36:C36) -> 5 | E36: =BC7 -> 1 | F36: =BC23 -> 0 | G36: =SUM(E36:F36) -> 1 | H36: =BD7 -> 1 | I36: =BD23 -> 1 | J36: =SUM(H36:I36) -> 2 | K36: =BE7 -> 1 | L36: =BE23 -> 2 | M36: =SUM(K36:L36) -> 3 | N36: =BF7 -> 3 | O36: =BF23 -> 4 | P36: =SUM(N36:O36) -> 7
A37: 04サービス | B37: =BB8 -> 2 | C37: =BB24 -> 2 | D37: =SUM(B37:C37) -> 4 | E37: =BC8 -> 1 | F37: =BC24 -> 3 | G37: =SUM(E37:F37) -> 4 | H37: =BD8 -> 1 | I37: =BD24 -> 1 | J37: =SUM(H37:I37) -> 2 | K37: =BE8 -> 1 | L37: =BE24 -> 1 | M37: =SUM(K37:L37) -> 2 | N37: =BF8 -> 3 | O37: =BF24 -> 1 | P37: =SUM(N37:O37) -> 4
A38: 05お客様対応 | B38: =BB9 -> 2 | C38: =BB25 -> 0 | D38: =SUM(B38:C38) -> 2 | E38: =BC9 -> 1 | F38: =BC25 -> 3 | G38: =SUM(E38:F38) -> 4 | H38: =BD9 -> 1 | I38: =BD25 -> 1 | J38: =SUM(H38:I38) -> 2 | K38: =BE9 -> 1 | L38: =BE25 -> 0 | M38: =SUM(K38:L38) -> 1 | N38: =BF9 -> 3 | O38: =BF25 -> 2 | P38: =SUM(N38:O38) -> 5
A39: 06設備 | B39: =BB10 -> 2 | C39: =BB26 -> 1 | D39: =SUM(B39:C39) -> 3 | E39: =BC10 -> 1 | F39: =BC26 -> 1 | G39: =SUM(E39:F39) -> 2 | H39: =BD10 -> 1 | I39: =BD26 -> 0 | J39: =SUM(H39:I39) -> 1 | K39: =BE10 -> 1 | L39: =BE26 -> 3 | M39: =SUM(K39:L39) -> 4 | N39: =BF10 -> 3 | O39: =BF26 -> 4 | P39: =SUM(N39:O39) -> 7
A40: 07資材 | B40: =BB11 -> 2 | C40: =BB27 -> 3 | D40: =SUM(B40:C40) -> 5 | E40: =BC11 -> 1 | F40: =BC27 -> 1 | G40: =SUM(E40:F40) -> 2 | H40: =BD11 -> 1 | I40: =BD27 -> 0 | J40: =SUM(H40:I40) -> 1 | K40: =BE11 -> 1 | L40: =BE27 -> 0 | M40: =SUM(K40:L40) -> 1 | N40: =BF11 -> 3 | O40: =BF27 -> 4 | P40: =SUM(N40:O40) -> 7
...

Sheet 班別コンピテンシー
A1: 【01本部長支援】コンピテンシー別出題マトリクス
A2: 班名 | B2: シーン | C2: No. | D2: 問題No. | E2: 共/個 | F2: ｺﾐｭﾆｹｰｼｮﾝ | G2: 情報収集 | H2: 情報分析 | I2: 想像・先読み | J2: 計画
A3: =問題!A3 -> 00全班共通 | B3: =問題!B3 -> シーン1 | C3: =問題!C3 -> 1 | D3: =問題!D3 -> 共通01 | E3: =問題!E3 -> 共通 | F3: =IF(問題!G3="●","〇","×") -> × | G3: =IF(問題!I3="●","〇","×") -> 〇 | H3: =IF(問題!K3="●","〇","×") -> × | I3: =IF(問題!M3="●","〇","×") -> 〇 | J3: =IF(問題!O3="●","〇","×") -> 〇
A4: =問題!A4 -> 00全班共通 | B4: =問題!B4 -> シーン1 | C4: =問題!C4 -> 2 | D4: =問題!D4 -> 共通02 | E4: =問題!E4 -> 共通 | F4: =IF(問題!G4="●","〇","×") -> × | G4: =IF(問題!I4="●","〇","×") -> 〇 | H4: =IF(問題!K4="●","〇","×") -> × | I4: =IF(問題!M4="●","〇","×") -> × | J4: =IF(問題!O4="●","〇","×") -> ×
A5: =問題!A5 -> 00全班共通 | B5: =問題!B5 -> シーン1 | C5: =問題!C5 -> 3 | D5: =問題!D5 -> 共通03 | E5: =問題!E5 -> 共通 | F5: =IF(問題!G5="●","〇","×") -> × | G5: =IF(問題!I5="●","〇","×") -> × | H5: =IF(問題!K5="●","〇","×") -> 〇 | I5: =IF(問題!M5="●","〇","×") -> × | J5: =IF(問題!O5="●","〇","×") -> ×
A6: =問題!A6 -> 00全班共通 | B6: =問題!B6 -> シーン1 | C6: =問題!C6 -> 4 | D6: =問題!D6 -> 共通04 | E6: =問題!E6 -> 共通 | F6: =IF(問題!G6="●","〇","×") -> × | G6: =IF(問題!I6="●","〇","×") -> 〇 | H6: =IF(問題!K6="●","〇","×") -> × | I6: =IF(問題!M6="●","〇","×") -> × | J6: =IF(問題!O6="●","〇","×") -> 〇
A7: =問題!A7 -> 00全班共通 | B7: =問題!B7 -> シーン1 | C7: =問題!C7 -> 5 | D7: =問題!D7 -> 共通05 | E7: =問題!E7 -> 共通 | F7: =IF(問題!G7="●","〇","×") -> × | G7: =IF(問題!I7="●","〇","×") -> × | H7: =IF(問題!K7="●","〇","×") -> × | I7: =IF(問題!M7="●","〇","×") -> 〇 | J7: =IF(問題!O7="●","〇","×") -> 〇
A8: =問題!A8 -> 00全班共通 | B8: =問題!B8 -> シーン1 | C8: =問題!C8 -> 6 | D8: =問題!D8 -> 共通06 | E8: =問題!E8 -> 共通 | F8: =IF(問題!G8="●","〇","×") -> × | G8: =IF(問題!I8="●","〇","×") -> 〇 | H8: =IF(問題!K8="●","〇","×") -> 〇 | I8: =IF(問題!M8="●","〇","×") -> 〇 | J8: =IF(問題!O8="●","〇","×") -> ×
A9: =問題!A9 -> 00全班共通 | B9: =問題!B9 -> シーン1 | C9: =問題!C9 -> 7 | D9: =問題!D9 -> 共通07 | E9: =問題!E9 -> 共通 | F9: =IF(問題!G9="●","〇","×") -> × | G9: =IF(問題!I9="●","〇","×") -> 〇 | H9: =IF(問題!K9="●","〇","×") -> × | I9: =IF(問題!M9="●","〇","×") -> × | J9: =IF(問題!O9="●","〇","×") -> 〇
A10: =問題!A10 -> 00全班共通 | B10: =問題!B10 -> シーン1 | C10: =問題!C10 -> 8 | D10: =問題!D10 -> 共通08 | E10: =問題!E10 -> 共通 | F10: =IF(問題!G10="●","〇","×") -> × | G10: =IF(問題!I10="●","〇","×") -> 〇 | H10: =IF(問題!K10="●","〇","×") -> 〇 | I10: =IF(問題!M10="●","〇","×") -> 〇 | J10: =IF(問題!O10="●","〇","×") -> ×
A11: =問題!A11 -> 01本部長支援 | B11: =問題!B11 -> シーン2 | C11: =問題!C11 -> 1 | D11: =問題!D11 -> 共通09 | E11: =問題!E11 -> 共通 | F11: =IF(問題!G11="●","〇","×") -> 〇 | G11: =IF(問題!I11="●","〇","×") -> 〇 | H11: =IF(問題!K11="●","〇","×") -> × | I11: =IF(問題!M11="●","〇","×") -> × | J11: =IF(問題!O11="●","〇","×") -> ×
A12: =問題!A12 -> 01本部長支援 | B12: =問題!B12 -> シーン2 | C12: =問題!C12 -> 2 | D12: =問題!D12 -> 共通10 | E12: =問題!E12 -> 共通 | F12: =IF(問題!G12="●","〇","×") -> 〇 | G12: =IF(問題!I12="●","〇","×") -> × | H12: =IF(問題!K12="●","〇","×") -> × | I12: =IF(問題!M12="●","〇","×") -> × | J12: =IF(問題!O12="●","〇","×") -> 〇
A13: =問題!A13 -> 01本部長支援 | B13: =問題!B13 -> シーン2 | C13: =問題!C13 -> 3 | D13: =問題!D13 -> 個別 | E13: =問題!E13 -> 個別 | F13: =IF(問題!G13="●","〇","×") -> 〇 | G13: =IF(問題!I13="●","〇","×") -> 〇 | H13: =IF(問題!K13="●","〇","×") -> × | I13: =IF(問題!M13="●","〇","×") -> × | J13: =IF(問題!O13="●","〇","×") -> 〇
A14: =問題!A14 -> 01本部長支援 | B14: =問題!B14 -> シーン2 | C14: =問題!C14 -> 4 | D14: =問題!D14 -> 個別 | E14: =問題!E14 -> 個別 | F14: =IF(問題!G14="●","〇","×") -> × | G14: =IF(問題!I14="●","〇","×") -> × | H14: =IF(問題!K14="●","〇","×") -> 〇 | I14: =IF(問題!M14="●","〇","×") -> 〇 | J14: =IF(問題!O14="●","〇","×") -> 〇
... A17: =問題!A17 -> 01本部長支援 | B17: =問題!B17 -> シーン2 | C17: =問題!C17 -> 7 | D17: =問題!D17 -> 共通11 | E17: =問題!E17 -> 共通 | F17: =IF(問題!G17="●","〇","×") -> 〇 | G17: =IF(問題!I17="●","〇","×") -> × | H17: =IF(問題!K17="●","〇","×") -> × | I17: =IF(問題!M17="●","〇","×") -> × | J17: =IF(問題!O17="●","〇","×") -> ×
A18: =問題!A81 -> 01本部長支援 | B18: =問題!B81 -> シーン3 | C18: =問題!C81 -> 1 | D18: =問題!D81 -> 共通12 | E18: =問題!E81 -> 共通 | F18: =IF(問題!G81="●","〇","×") -> 〇 | G18: =IF(問題!I81="●","〇","×") -> × | H18: =IF(問題!K81="●","〇","×") -> × | I18: =IF(問題!M81="●","〇","×") -> × | J18: =IF(問題!O81="●","〇","×") -> 〇
A19: =問題!A82 -> 01本部長支援 | B19: =問題!B82 -> シーン3 | C19: =問題!C82 -> 2 | D19: =問題!D82 -> 個別 | E19: =問題!E82 -> 個別 | F19: =IF(問題!G82="●","〇","×") -> × | G19: =IF(問題!I82="●","〇","×") -> × | H19: =IF(問題!K82="●","〇","×") -> 〇 | I19: =IF(問題!M82="●","〇","×") -> 〇 | J19: =IF(問題!O82="●","〇","×") -> 〇
A20: =問題!A83 -> 01本部長支援 | B20: =問題!B83 -> シーン3 | C20: =問題!C83 -> 3 | D20: =問題!D83 -> 個別 | E20: =問題!E83 -> 個別 | F20: =IF(問題!G83="●","〇","×") -> × | G20: =IF(問題!I83="●","〇","×") -> 〇 | H20: =IF(問題!K83="●","〇","×") -> × | I20: =IF(問題!M83="●","〇","×") -> × | J20: =IF(問題!O83="●","〇","×") -> 〇
A21: =問題!A84 -> 01本部長支援 | B21: =問題!B84 -> シーン3 | C21: =問題!C84 -> 4 | D21: =問題!D84 -> 共通13 | E21: =問題!E84 -> 共通 | F21: =IF(問題!G84="●","〇","×") -> 〇 | G21: =IF(問題!I84="●","〇","×") -> 〇 | H21: =IF(問題!K84="●","〇","×") -> × | I21: =IF(問題!M84="●","〇","×") -> × | J21: =IF(問題!O84="●","〇","×") -> 〇
A22: =問題!A85 -> 01本部長支援 | B22: =問題!B85 -> シーン3 | C22: =問題!C85 -> 5 | D22: =問題!D85 -> 個別 | E22: =問題!E85 -> 個別 | F22: =IF(問題!G85="●","〇","×") -> 〇 | G22: =IF(問題!I85="●","〇","×") -> × | H22: =IF(問題!K85="●","〇","×") -> × | I22: =IF(問題!M85="●","〇","×") -> × | J22: =IF(問題!O85="●","〇","×") -> ×
A23: =問題!A86 -> 01本部長支援 | B23: =問題!B86 -> シーン3 | C23: =問題!C86 -> 6 | D23: =問題!D86 -> 個別 | E23: =問題!E86 -> 個別 | F23: =IF(問題!G86="●","〇","×") -> 〇 | G23: =IF(問題!I86="●","〇","×") -> 〇 | H23: =IF(問題!K86="●","〇","×") -> × | I23: =IF(問題!M86="●","〇","×") -> × | J23: =IF(問題!O86="●","〇","×") -> ×
A24: =問題!A87 -> 01本部長支援 | B24: =問題!B87 -> シーン3 | C24: =問題!C87 -> 7 | D24: =問題!D87 -> 共通14 | E24: =問題!E87 -> 共通 | F24: =IF(問題!G87="●","〇","×") -> × | G24: =IF(問題!I87="●","〇","×") -> × | H24: =IF(問題!K87="●","〇","×") -> 〇 | I24: =IF(問題!M87="●","〇","×") -> 〇 | J24: =IF(問題!O87="●","〇","×") -> 〇
A25: 合計 | E25: 〇の数 | F25: =COUNTIF(F3:F24,"〇") -> 10 | G25: =COUNTIF(G3:G24,"〇") -> 12 | H25: =COUNTIF(H3:H24,"〇") -> 6 | I25: =COUNTIF(I3:I24,"〇") -> 7 | J25: =COUNTIF(J3:J24,"〇") -> 12
A27: 【02広報】コンピテンシー別出題マトリクス
A28: 班名 | B28: シーン | C28: No. | D28: 問題No. | E28: 共/個 | F28: ｺﾐｭﾆｹｰｼｮﾝ | G28: 情報収集 | H28: 情報分析 | I28: 想像・先読み | J28: 計画
A29: =問題!A3 -> 00全班共通 | B29: =問題!B3 -> シーン1 | C29: =問題!C3 -> 1 | D29: =問題!D3 -> 共通01 | E29: =問題!E3 -> 共通 | F29: =IF(問題!G3="●","〇","×") -> × | G29: =IF(問題!I3="●","〇","×") -> 〇 | H29: =IF(問題!K3="●","〇","×") -> × | I29: =IF(問題!M3="●","〇","×") -> 〇 | J29: =IF(問題!O3="●","〇","×") -> 〇
A30: =問題!A4 -> 00全班共通 | B30: =問題!B4 -> シーン1 | C30: =問題!C4 -> 2 | D30: =問題!D4 -> 共通02 | E30: =問題!E4 -> 共通 | F30: =IF(問題!G4="●","〇","×") -> × | G30: =IF(問題!I4="●","〇","×") -> 〇 | H30: =IF(問題!K4="●","〇","×") -> × | I30: =IF(問題!M4="●","〇","×") -> × | J30: =IF(問題!O4="●","〇","×") -> ×
A31: =問題!A5 -> 00全班共通 | B31: =問題!B5 -> シーン1 | C31: =問題!C5 -> 3 | D31: =問題!D5 -> 共通03 | E31: =問題!E5 -> 共通 | F31: =IF(問題!G5="●","〇","×") -> × | G31: =IF(問題!I5="●","〇","×") -> × | H31: =IF(問題!K5="●","〇","×") -> 〇 | I31: =IF(問題!M5="●","〇","×") -> × | J31: =IF(問題!O5="●","〇","×") -> ×
A32: =問題!A6 -> 00全班共通 | B32: =問題!B6 -> シーン1 | C32: =問題!C6 -> 4 | D32: =問題!D6 -> 共通04 | E32: =問題!E6 -> 共通 | F32: =IF(問題!G6="●","〇","×") -> × | G32: =IF(問題!I6="●","〇","×") -> 〇 | H32: =IF(問題!K6="●","〇","×") -> × | I32: =IF(問題!M6="●","〇","×") -> × | J32: =IF(問題!O6="●","〇","×") -> 〇
A33: =問題!A7 -> 00全班共通 | B33: =問題!B7 -> シーン1 | C33: =問題!C7 -> 5 | D33: =問題!D7 -> 共通05 | E33: =問題!E7 -> 共通 | F33: =IF(問題!G7="●","〇","×") -> × | G33: =IF(問題!I7="●","〇","×") -> × | H33: =IF(問題!K7="●","〇","×") -> × | I33: =IF(問題!M7="●","〇","×") -> 〇 | J33: =IF(問題!O7="●","〇","×") -> 〇
A34: =問題!A8 -> 00全班共通 | B34: =問題!B8 -> シーン1 | C34: =問題!C8 -> 6 | D34: =問題!D8 -> 共通06 | E34: =問題!E8 -> 共通 | F34: =IF(問題!G8="●","〇","×") -> × | G34: =IF(問題!I8="●","〇","×") -> 〇 | H34: =IF(問題!K8="●","〇","×") -> 〇 | I34: =IF(問題!M8="●","〇","×") -> 〇 | J34: =IF(問題!O8="●","〇","×") -> ×
A35: =問題!A9 -> 00全班共通 | B35: =問題!B9 -> シーン1 | C35: =問題!C9 -> 7 | D35: =問題!D9 -> 共通07 | E35: =問題!E9 -> 共通 | F35: =IF(問題!G9="●","〇","×") -> × | G35: =IF(問題!I9="●","〇","×") -> 〇 | H35: =IF(問題!K9="●","〇","×") -> × | I35: =IF(問題!M9="●","〇","×") -> × | J35: =IF(問題!O9="●","〇","×") -> 〇
A36: =問題!A10 -> 00全班共通 | B36: =問題!B10 -> シーン1 | C36: =問題!C10 -> 8 | D36: =問題!D10 -> 共通08 | E36: =問題!E10 -> 共通 | F36: =IF(問題!G10="●","〇","×") -> × | G36: =IF(問題!I10="●","〇","×") -> 〇 | H36: =IF(問題!K10="●","〇","×") -> 〇 | I36: =IF(問題!M10="●","〇","×") -> 〇 | J36: =IF(問題!O10="●","〇","×") -> ×
A37: =問題!A18 -> 02広報 | B37: =問題!B18 -> シーン2 | C37: =問題!C18 -> 1 | D37: =問題!D18 -> 共通09 | E37: =問題!E18 -> 共通 | F37: =IF(問題!G18="●","〇","×") -> 〇 | G37: =IF(問題!I18="●","〇","×") -> 〇 | H37: =IF(問題!K18="●","〇","×") -> × | I37: =IF(問題!M18="●","〇","×") -> × | J37: =IF(問題!O18="●","〇","×") -> ×
A38: =問題!A19 -> 02広報 | B38: =問題!B19 -> シーン2 | C38: =問題!C19 -> 2 | D38: =問題!D19 -> 共通10 | E38: =問題!E19 -> 共通 | F38: =IF(問題!G19="●","〇","×") -> 〇 | G38: =IF(問題!I19="●","〇","×") -> × | H38: =IF(問題!K19="●","〇","×") -> × | I38: =IF(問題!M19="●","〇","×") -> × | J38: =IF(問題!O19="●","〇","×") -> 〇
A39: =問題!A20 -> 02広報 | B39: =問題!B20 -> シーン2 | C39: =問題!C20 -> 3 | D39: =問題!D20 -> 個別 | E39: =問題!E20 -> 個別 | F39: =IF(問題!G20="●","〇","×") -> × | G39: =IF(問題!I20="●","〇","×") -> 〇 | H39: =IF(問題!K20="●","〇","×") -> × | I39: =IF(問題!M20="●","〇","×") -> × | J39: =IF(問題!O20="●","〇","×") -> 〇
A40: =問題!A21 -> 02広報 | B40: =問題!B21 -> シーン2 | C40: =問題!C21 -> 4 | D40: =問題!D21 -> 個別 | E40: =問題!E21 -> 個別 | F40: =IF(問題!G21="●","〇","×") -> 〇 | G40: =IF(問題!I21="●","〇","×") -> 〇 | H40: =IF(問題!K21="●","〇","×") -> × | I40: =IF(問題!M21="●","〇","×") -> × | J40: =IF(問題!O21="●","〇","×") -> ×
A41: =問題!A22 -> 02広報 | B41: =問題!B22 -> シーン2 | C41: =問題!C22 -> 5 | D41: =問題!D22 -> 個別 | E41: =問題!E22 -> 個別 | F41: =IF(問題!G22="●","〇","×") -> × | G41: =IF(問題!I22="●","〇","×") -> × | H41: =IF(問題!K22="●","〇","×") -> × | I41: =IF(問題!M22="●","〇","×") -> × | J41: =IF(問題!O22="●","〇","×") -> 〇
A42: =問題!A23 -> 02広報 | B42: =問題!B23 -> シーン2 | C42: =問題!C23 -> 6 | D42: =問題!D23 -> 個別 | E42: =問題!E23 -> 個別 | F42: =IF(問題!G23="●","〇","×") -> × | G42: =IF(問題!I23="●","〇","×") -> × | H42: =IF(問題!K23="●","〇","×") -> 〇 | I42: =IF(問題!M23="●","〇","×") -> 〇 | J42: =IF(問題!O23="●","〇","×") -> ×
A43: =問題!A24 -> 02広報 | B43: =問題!B24 -> シーン2 | C43: =問題!C24 -> 7 | D43: =問題!D24 -> 共通11 | E43: =問題!E24 -> 共通 | F43: =IF(問題!G24="●","〇","×") -> 〇 | G43: =IF(問題!I24="●","〇","×") -> × | H43: =IF(問題!K24="●","〇","×") -> × | I43: =IF(問題!M24="●","〇","×") -> × | J43: =IF(問題!O24="●","〇","×") -> ×
...
